<?xml version="1.0" ?>
<!-- =================================================================================== -->
<!-- |    This document was autogenerated by xacro from /home/user/testube_ws/src/ur5e_moveit/urdf/ur5ehand.urdf.xacro | -->
<!-- |    EDITING THIS FILE BY HAND IS NOT RECOMMENDED                                 | -->
<!-- =================================================================================== -->
<robot name="ur5e_robot">
    <transmission name="shoulder_pan_trans">
        <type>transmission_interface/SimpleTransmission</type>
        <joint name="shoulder_pan_joint">
            <hardwareInterface>hardware_interface/PositionJointInterface</hardwareInterface>
        </joint>
        <actuator name="shoulder_pan_motor">
            <mechanicalReduction>1</mechanicalReduction>
            <hardwareInterface>hardware_interface/PositionJointInterface</hardwareInterface>
        </actuator>
    </transmission>
    <transmission name="shoulder_lift_trans">
        <type>transmission_interface/SimpleTransmission</type>
        <joint name="shoulder_lift_joint">
            <hardwareInterface>hardware_interface/PositionJointInterface</hardwareInterface>
        </joint>
        <actuator name="shoulder_lift_motor">
            <mechanicalReduction>1</mechanicalReduction>
            <hardwareInterface>hardware_interface/PositionJointInterface</hardwareInterface>
        </actuator>
    </transmission>
    <transmission name="elbow_trans">
        <type>transmission_interface/SimpleTransmission</type>
        <joint name="elbow_joint">
            <hardwareInterface>hardware_interface/PositionJointInterface</hardwareInterface>
        </joint>
        <actuator name="elbow_motor">
            <mechanicalReduction>1</mechanicalReduction>
            <hardwareInterface>hardware_interface/PositionJointInterface</hardwareInterface>
        </actuator>
    </transmission>
    <transmission name="wrist_1_trans">
        <type>transmission_interface/SimpleTransmission</type>
        <joint name="wrist_1_joint">
            <hardwareInterface>hardware_interface/PositionJointInterface</hardwareInterface>
        </joint>
        <actuator name="wrist_1_motor">
            <mechanicalReduction>1</mechanicalReduction>
            <hardwareInterface>hardware_interface/PositionJointInterface</hardwareInterface>
        </actuator>
    </transmission>
    <transmission name="wrist_2_trans">
        <type>transmission_interface/SimpleTransmission</type>
        <joint name="wrist_2_joint">
            <hardwareInterface>hardware_interface/PositionJointInterface</hardwareInterface>
        </joint>
        <actuator name="wrist_2_motor">
            <mechanicalReduction>1</mechanicalReduction>
            <hardwareInterface>hardware_interface/PositionJointInterface</hardwareInterface>
        </actuator>
    </transmission>
    <transmission name="wrist_3_trans">
        <type>transmission_interface/SimpleTransmission</type>
        <joint name="wrist_3_joint">
            <hardwareInterface>hardware_interface/PositionJointInterface</hardwareInterface>
        </joint>
        <actuator name="wrist_3_motor">
            <mechanicalReduction>1</mechanicalReduction>
            <hardwareInterface>hardware_interface/PositionJointInterface</hardwareInterface>
        </actuator>
    </transmission>
    <link name="world" />
    <link name="base_link_inertia">
        <visual>
            <origin rpy="0 0 3.141592653589793" xyz="0 0 0" />
            <geometry>
                <mesh filename="package://ur5e_moveit/meshes/visual/base.dae" />
            </geometry>
            <material name="LightGrey">
                <color rgba="0.7 0.7 0.7 1.0" />
            </material>
        </visual>
        <collision>
            <origin rpy="0 0 3.141592653589793" xyz="0 0 0" />
            <geometry>
                <mesh filename="package://ur5e_moveit/meshes/collision/base.stl" />
            </geometry>
        </collision>
        <inertial>
            <mass value="4.0" />
            <origin rpy="0 0 0" xyz="0 0 0" />
            <inertia ixx="0.00443333156" ixy="0.0" ixz="0.0" iyy="0.00443333156" iyz="0.0" izz="0.0072" />
        </inertial>
    </link>
    <link name="shoulder_link">
        <visual>
            <origin rpy="0 0 3.141592653589793" xyz="0 0 0" />
            <geometry>
                <mesh filename="package://ur5e_moveit/meshes/visual/shoulder.dae" />
            </geometry>
            <material name="LightGrey">
                <color rgba="0.7 0.7 0.7 1.0" />
            </material>
        </visual>
        <collision>
            <origin rpy="0 0 3.141592653589793" xyz="0 0 0" />
            <geometry>
                <mesh filename="package://ur5e_moveit/meshes/collision/shoulder.stl" />
            </geometry>
        </collision>
        <inertial>
            <mass value="3.7" />
            <origin rpy="0 0 0" xyz="0 0 0" />
            <inertia ixx="0.010267495893" ixy="0.0" ixz="0.0" iyy="0.010267495893" iyz="0.0" izz="0.00666" />
        </inertial>
    </link>
    <link name="upper_arm_link">
        <visual>
            <origin rpy="1.5707963267948966 0 -1.5707963267948966" xyz="0 0 0.138" />
            <geometry>
                <mesh filename="package://ur5e_moveit/meshes/visual/upperarm.dae" />
            </geometry>
            <material name="LightGrey">
                <color rgba="0.7 0.7 0.7 1.0" />
            </material>
        </visual>
        <collision>
            <origin rpy="1.5707963267948966 0 -1.5707963267948966" xyz="0 0 0.138" />
            <geometry>
                <mesh filename="package://ur5e_moveit/meshes/collision/upperarm.stl" />
            </geometry>
        </collision>
        <inertial>
            <mass value="8.393" />
            <origin rpy="0 1.5707963267948966 0" xyz="-0.2125 0.0 0.138" />
            <inertia ixx="0.1338857818623325" ixy="0.0" ixz="0.0" iyy="0.1338857818623325" iyz="0.0" izz="0.0151074" />
        </inertial>
    </link>
    <link name="forearm_link">
        <visual>
            <origin rpy="1.5707963267948966 0 -1.5707963267948966" xyz="0 0 0.007" />
            <geometry>
                <mesh filename="package://ur5e_moveit/meshes/visual/forearm.dae" />
            </geometry>
            <material name="LightGrey">
                <color rgba="0.7 0.7 0.7 1.0" />
            </material>
        </visual>
        <collision>
            <origin rpy="1.5707963267948966 0 -1.5707963267948966" xyz="0 0 0.007" />
            <geometry>
                <mesh filename="package://ur5e_moveit/meshes/collision/forearm.stl" />
            </geometry>
        </collision>
        <inertial>
            <mass value="2.275" />
            <origin rpy="0 1.5707963267948966 0" xyz="-0.1961 0.0 0.007" />
            <inertia ixx="0.031209355099586295" ixy="0.0" ixz="0.0" iyy="0.031209355099586295" iyz="0.0" izz="0.004095" />
        </inertial>
    </link>
    <link name="wrist_1_link">
        <visual>
            <origin rpy="1.5707963267948966 0 0" xyz="0 0 -0.127" />
            <geometry>
                <mesh filename="package://ur5e_moveit/meshes/visual/wrist1.dae" />
            </geometry>
            <material name="LightGrey">
                <color rgba="0.7 0.7 0.7 1.0" />
            </material>
        </visual>
        <collision>
            <origin rpy="1.5707963267948966 0 0" xyz="0 0 -0.127" />
            <geometry>
                <mesh filename="package://ur5e_moveit/meshes/collision/wrist1.stl" />
            </geometry>
        </collision>
        <inertial>
            <mass value="1.219" />
            <origin rpy="0 0 0" xyz="0 0 0" />
            <inertia ixx="0.0025598989760400002" ixy="0.0" ixz="0.0" iyy="0.0025598989760400002" iyz="0.0" izz="0.0021942" />
        </inertial>
    </link>
    <link name="wrist_2_link">
        <visual>
            <origin rpy="0 0 0" xyz="0 0 -0.0997" />
            <geometry>
                <mesh filename="package://ur5e_moveit/meshes/visual/wrist2.dae" />
            </geometry>
            <material name="LightGrey">
                <color rgba="0.7 0.7 0.7 1.0" />
            </material>
        </visual>
        <collision>
            <origin rpy="0 0 0" xyz="0 0 -0.0997" />
            <geometry>
                <mesh filename="package://ur5e_moveit/meshes/collision/wrist2.stl" />
            </geometry>
        </collision>
        <inertial>
            <mass value="1.219" />
            <origin rpy="0 0 0" xyz="0 0 0" />
            <inertia ixx="0.0025598989760400002" ixy="0.0" ixz="0.0" iyy="0.0025598989760400002" iyz="0.0" izz="0.0021942" />
        </inertial>
    </link>
    <link name="wrist_3_link">
        <visual>
            <origin rpy="1.5707963267948966 0 0" xyz="0 0 -0.0989" />
            <geometry>
                <mesh filename="package://ur5e_moveit/meshes/visual/wrist3.dae" />
            </geometry>
            <material name="LightGrey">
                <color rgba="0.7 0.7 0.7 1.0" />
            </material>
        </visual>
        <collision>
            <origin rpy="1.5707963267948966 0 0" xyz="0 0 -0.0989" />
            <geometry>
                <mesh filename="package://ur5e_moveit/meshes/collision/wrist3.stl" />
            </geometry>
        </collision>
        <inertial>
            <mass value="0.1879" />
            <origin rpy="0 0 0" xyz="0.0 0.0 -0.0229" />
            <inertia ixx="9.890410052167731e-05" ixy="0.0" ixz="0.0" iyy="9.890410052167731e-05" iyz="0.0" izz="0.0001321171875" />
        </inertial>
    </link>
    <joint name="world-base_link_inertia" type="fixed">
        <parent link="world" />
        <child link="base_link_inertia" />
        <origin rpy="0 0 3.141592653589793" xyz="0 0 0" />
    </joint>
    <joint name="shoulder_pan_joint" type="revolute">
        <parent link="base_link_inertia" />
        <child link="shoulder_link" />
        <origin rpy="0 0 0" xyz="0 0 0.1625" />
        <axis xyz="0 0 1" />
        <limit effort="150.0" lower="-6.283185307179586" upper="6.283185307179586" velocity="3.141592653589793" />
        <dynamics damping="0" friction="0" />
    </joint>
    <joint name="shoulder_lift_joint" type="revolute">
        <parent link="shoulder_link" />
        <child link="upper_arm_link" />
        <origin rpy="1.570796327 0 0" xyz="0 0 0" />
        <axis xyz="0 0 1" />
        <limit effort="150.0" lower="-6.283185307179586" upper="6.283185307179586" velocity="3.141592653589793" />
        <dynamics damping="0" friction="0" />
    </joint>
    <joint name="elbow_joint" type="revolute">
        <parent link="upper_arm_link" />
        <child link="forearm_link" />
        <origin rpy="0 0 0" xyz="-0.425 0 0" />
        <axis xyz="0 0 1" />
        <limit effort="150.0" lower="-3.141592653589793" upper="3.141592653589793" velocity="3.141592653589793" />
        <dynamics damping="0" friction="0" />
    </joint>
    <joint name="wrist_1_joint" type="revolute">
        <parent link="forearm_link" />
        <child link="wrist_1_link" />
        <origin rpy="0 0 0" xyz="-0.3922 0 0.1333" />
        <axis xyz="0 0 1" />
        <limit effort="28.0" lower="-6.283185307179586" upper="6.283185307179586" velocity="3.141592653589793" />
        <dynamics damping="0" friction="0" />
    </joint>
    <joint name="wrist_2_joint" type="revolute">
        <parent link="wrist_1_link" />
        <child link="wrist_2_link" />
        <origin rpy="1.570796327 0 0" xyz="0 -0.0997 -2.044881182297852e-11" />
        <axis xyz="0 0 1" />
        <limit effort="28.0" lower="-6.283185307179586" upper="6.283185307179586" velocity="3.141592653589793" />
        <dynamics damping="0" friction="0" />
    </joint>
    <joint name="wrist_3_joint" type="revolute">
        <parent link="wrist_2_link" />
        <child link="wrist_3_link" />
        <origin rpy="1.570796326589793 3.141592653589793 3.141592653589793" xyz="0 0.0996 -2.042830148012698e-11" />
        <axis xyz="0 0 1" />
        <limit effort="28.0" lower="-6.283185307179586" upper="6.283185307179586" velocity="3.141592653589793" />
        <dynamics damping="0" friction="0" />
    </joint>
    <gazebo>
        <plugin filename="libgazebo_ros_control.so" name="gazebo_ros_control">
            <robotNamespace>/ur5e</robotNamespace>
            <robotSimType>gazebo_ros_control/DefaultRobotHWSim</robotSimType>
            <legacyModeNS>true</legacyModeNS>
        </plugin>
    </gazebo>
    <!-- Define white material -->
    <material name="white">
        <color rgba="1 1 1 1" />
    </material>
    <!-- Camera internal frame -->
    <link name="wrist_realsense" />
    <link name="wrist_realsense_gazebo" />
    <!-- Transform between camera base and gazebo plugin frame -->
    <joint name="wrist_realsense_gazebo_joint" type="fixed">
        <parent link="wrist_realsense" />
        <child link="wrist_realsense_gazebo" />
        <origin rpy="-1.5707963 0 -1.5707963" xyz="0.0 0 0" />
    </joint>
    <!-- Gazebo sensor plugin -->
    <gazebo reference="wrist_realsense">
        <turnGravityOff>true</turnGravityOff>
        <sensor name="wrist_realsense_depth" type="depth">
            <always_on>true</always_on>
            <update_rate>30</update_rate>
            <camera>
                <horizontal_fov>1.5184352</horizontal_fov>
                <image>
                    <width>640</width>
                    <height>480</height>
                    <format>RGB8</format>
                </image>
                <clip>
                    <near>0.01</near>
                    <far>50.0</far>
                </clip>
            </camera>
            <plugin filename="libgazebo_ros_openni_kinect.so" name="wrist_realsense_controller">
                <cameraName>wrist/realsense</cameraName>
                <imageTopicName>color/image_raw</imageTopicName>
                <cameraInfoTopicName>color/camera_info</cameraInfoTopicName>
                <depthImageTopicName>depth/image_raw</depthImageTopicName>
                <depthImageInfoTopicName>depth/camera_info</depthImageInfoTopicName>
                <pointCloudTopicName>depth/color/points</pointCloudTopicName>
                <frameName>wrist_realsense_gazebo</frameName>
                <pointCloudCutoff>0.1</pointCloudCutoff>
                <pointCloudCutoffMax>8.0</pointCloudCutoffMax>
            </plugin>
        </sensor>
    </gazebo>
    <!-- Visual and collision for RealSense body -->
    <link name="wrist_realsense_lens">
        <visual>
            <origin rpy="1.5707963267948966 0 1.5707963267948966" xyz="0.02 0 0" />
            <geometry>
                <mesh filename="package://ur5e_moveit/meshes/camera/d435.dae" />
            </geometry>
            <material name="white" />
        </visual>
        <collision>
            <origin rpy="1.5707963267948966 0 1.5707963267948966" xyz="0.01 0 0" />
            <geometry>
                <box size="0.07 0.025 0.02" />
            </geometry>
        </collision>
        <inertial>
            <mass value="0.2" />
            <origin rpy="0 0 0" xyz="0 0 0" />
            <inertia ixx="1e-4" ixy="0" ixz="0" iyy="1e-4" iyz="0" izz="1e-4" />
        </inertial>
    </link>
    <!-- Mount lens to wrist_3_link -->
    <!-- <joint name="wrist_realsense_lens_joint" type="fixed">
      <origin xyz="0.003 0.054 0.017" rpy="0 ${-pi/2} ${-pi/2}" />
      <parent link="${parent_link}" />
      <child link="wrist_realsense_lens" />
    </joint> -->
    <joint name="wrist_realsense_lens_joint" type="fixed">
        <origin rpy="0 0.523599 0.785" xyz="-1.0 -1.0 0.75" />
        <!-- Looking down at an angle -->
        <parent link="world" />
        <child link="wrist_realsense_lens" />
    </joint>
    <!-- Internal camera connection -->
    <joint name="wrist_realsense_joint" type="fixed">
        <origin rpy="0 0 0" xyz="0.025 0 0" />
        <parent link="wrist_realsense_lens" />
        <child link="wrist_realsense" />
    </joint>
    <joint name="gripper_robotiq_hande_base_joint" type="fixed">
        <parent link="wrist_3_link" />
        <child link="gripper_robotiq_hande_base_link" />
        <origin rpy="0 -1.5707963267948966 -1.5707963267948966" xyz="0 0 0" />
    </joint>
    <link name="gripper_robotiq_hande_base_link">
        <inertial>
            <origin rpy="1.5707963267948966 0 1.5707963267948966" xyz="0 0 0.04607" />
            <mass value="0.86387" />
            <inertia ixx="1017560E-9" ixy="0" ixz="2235E-9" iyy="1028041E-9" iyz="0" izz="489810E-9" />
        </inertial>
        <visual>
            <origin rpy="1.5707963267948966 0 1.5707963267948966" xyz="0 0 0" />
            <geometry>
                <mesh filename="package://ur5e_moveit/meshes/gripper/visual/hand-e.dae" scale="0.001 0.001 0.001" />
            </geometry>
            <material name="Gazebo/Black">
                <color rgba="0.1 0.1 0.1 1" />
            </material>
        </visual>
        <collision>
            <origin rpy="1.5707963267948966 0 1.5707963267948966" xyz="0 0 0" />
            <geometry>
                <mesh filename="package://ur5e_moveit/meshes/gripper/visual/hand-e.dae" scale="0.001 0.001 0.001" />
            </geometry>
        </collision>
    </link>
    <gazebo reference="gripper_robotiq_hande_base_link">
        <material>Gazebo/Black</material>
        <selfCollide>True</selfCollide>
    </gazebo>
    <link name="gripper_robotiq_hande_left_finger">
        <inertial>
            <origin rpy="1.5707963267948966 0 1.5707963267948966" xyz="0.02262 -0.00759 0.00738" />
            <mass value="0.03804" />
            <inertia ixx="13567E-9" ixy="1849E-9" ixz="3622E-9" iyy="15784E-9" iyz="3616E-9" izz="7478E-9" />
        </inertial>
        <visual>
            <origin rpy="1.5707963267948966 0 1.5707963267948966" xyz="0 0 0" />
            <geometry>
                <mesh filename="package://ur5e_moveit/meshes/gripper/visual/hand-e_finger_1.dae" scale="0.001 0.001 0.001" />
            </geometry>
            <material name="Gazebo/Grey">
                <color rgba="0.1 0.1 0.1 1" />
            </material>
        </visual>
        <collision>
            <origin rpy="1.5707963267948966 0 1.5707963267948966" xyz="0 0 0" />
            <geometry>
                <mesh filename="package://ur5e_moveit/meshes/gripper/visual/hand-e_finger_1.dae" scale="0.001 0.001 0.001" />
            </geometry>
        </collision>
    </link>
    <gazebo reference="gripper_robotiq_hande_left_finger">
        <material>Gazebo/Grey</material>
        <selfCollide>True</selfCollide>
    </gazebo>
    <link name="gripper_robotiq_hande_right_finger">
        <inertial>
            <origin rpy="1.5707963267948966 0 1.5707963267948966" xyz="-0.02262 0.00759 0.00738" />
            <mass value="0.03804" />
            <inertia ixx="13567E-9" ixy="1849E-9" ixz="-3622E-9" iyy="15784E-9" iyz="-3616E-9" izz="7478E-9" />
        </inertial>
        <visual>
            <origin rpy="1.5707963267948966 0 1.5707963267948966" xyz="0 0 0" />
            <geometry>
                <mesh filename="package://ur5e_moveit/meshes/gripper/visual/hand-e_finger_2.dae" scale="0.001 0.001 0.001" />
            </geometry>
            <material name="Gazebo/Grey">
                <color rgba="0.1 0.1 0.1 1" />
            </material>
        </visual>
        <collision>
            <origin rpy="1.5707963267948966 0 1.5707963267948966" xyz="0 0 0" />
            <geometry>
                <mesh filename="package://ur5e_moveit/meshes/gripper/visual/hand-e_finger_2.dae" scale="0.001 0.001 0.001" />
            </geometry>
        </collision>
    </link>
    <gazebo reference="gripper_robotiq_hande_right_finger">
        <material>Gazebo/Grey</material>
        <selfCollide>True</selfCollide>
    </gazebo>
    <joint name="gripper_robotiq_hande_joint_finger" type="prismatic">
        <origin rpy="0 0 0" xyz="0.099 0 0" />
        <parent link="gripper_robotiq_hande_base_link" />
        <child link="gripper_robotiq_hande_left_finger" />
        <axis xyz="0 -1 0" />
        <limit effort="130" lower="0" upper="0.025" velocity="0.15" />
        <dynamics damping="0.1" friction="0" />
    </joint>
    <joint name="gripper_robotiq_hande_base_to_right_finger" type="prismatic">
        <origin rpy="0 0 0" xyz="0.099 0 0" />
        <parent link="gripper_robotiq_hande_base_link" />
        <child link="gripper_robotiq_hande_right_finger" />
        <axis xyz="0 1 0" />
        <limit effort="130" lower="0" upper="0.025" velocity="0.15" />
        <mimic joint="gripper_robotiq_hande_joint_finger" multiplier="1" offset="0" />
    </joint>
    <transmission name="gripper_robotiq_hande_joint_finger_trans">
        <type>transmission_interface/SimpleTransmission</type>
        <joint name="gripper_robotiq_hande_joint_finger">
            <hardwareInterface>hardware_interface/EffortJointInterface</hardwareInterface>
        </joint>
        <actuator name="gripper_robotiq_hande_joint_finger_motor">
            <mechanicalReduction>1</mechanicalReduction>
            <hardwareInterface>hardware_interface/EffortJointInterface</hardwareInterface>
        </actuator>
    </transmission>
    <gazebo>
        <plugin filename="libroboticsgroup_upatras_gazebo_mimic_joint_plugin.so" name="gripper_mimic_robotiq_hande">
            <joint>gripper_robotiq_hande_joint_finger</joint>
            <mimicJoint>gripper_robotiq_hande_base_to_right_finger</mimicJoint>
            <multiplier>1.0</multiplier>
            <offset>0</offset>
        </plugin>
    </gazebo>
    <transmission name="trans_gripper_robotiq_hande_base_to_right_finger">
        <type>transmission_interface/SimpleTransmission</type>
        <joint name="gripper_robotiq_hande_base_to_right_finger">
            <hardwareInterface>hardware_interface/EffortJointInterface</hardwareInterface>
        </joint>
        <actuator name="gripper_robotiq_hande_base_to_right_finger_motor">
            <hardwareInterface>hardware_interface/EffortJointInterface</hardwareInterface>
            <mechanicalReduction>1</mechanicalReduction>
        </actuator>
    </transmission>
</robot>
